<?xml version="1.0"?>
<robot name="car4" xmlns:xacro="http://www.ros.org/wiki/xacro">


    <xacro:property name="base_length" value="1.0" />
    <xacro:property name="base_width" value="0.5" />
    <xacro:property name="base_height" value="0.2" />
    <xacro:property name="wheel_radius" value="0.15" />
    <xacro:property name="wheel_length" value="0.1" />
    <xacro:property name="column_radius" value="0.05" />
    <xacro:property name="column_length" value="0.5" />

    <xacro:macro name="box_inertia" params="m l w h xyz rpy">
        <inertial>
            <origin xyz="${xyz}" rpy="${rpy}" />
            <mass value="${m}" />
            <inertia ixx="${(m/12)*(h*h + l*l)}" ixy="0.0" ixz="0.0" 
                     iyy="${(m/12)*(w*w + l*l)}" iyz="0.0" 
                     izz="${(m/12)*(w*w + h*h)}"/>
        </inertial>
    </xacro:macro>

     <xacro:macro name="wheel_inertia" params="m r l xyz rpy">
        <inertial>
            <origin xyz="${xyz}" rpy="${rpy}" />
            <mass value="${m}" />
            <inertia ixx="${(m/12)*(3*r*r + l*l)}" ixy="0.0" ixz="0.0" 
                     iyy="${(m/12)*(3*r*r + l*l)}" iyz="0.0" 
                     izz="${(m*r*r)/2}"/>
        </inertial>
    </xacro:macro>

    <xacro:macro name="column_inertia" params="m r l xyz rpy">
        <inertial>
            <origin xyz="${xyz}" rpy="${rpy}" />
            <mass value="${m}" />
            <inertia ixx="${(m/12)*(3*r*r + l*l)}" ixy="0.0" ixz="0.0" 
                     iyy="${(m/12)*(3*r*r + l*l)}" iyz="0.0" 
                     izz="${(m*r*r)/2}"/>
        </inertial>
    </xacro:macro>




    <material name="orange">
        <color rgba="1 0.6 0 1" />
    </material>

    <material name="grey">
        <color rgba="0.5 0.5 0.5 1" />
    </material>

    <material name="black">
        <color rgba="0.0 0.0 0.0 1" />
    </material>

    




    <link name="base_footprint" />



    <link name="base_link">
        <visual>
            <geometry>
                <box size="${base_length} ${base_width} ${base_height}"/> 
            </geometry>
            <origin xyz="0 0 0.1" rpy="0 0 0"/>
            <material name="orange" />
        </visual>
        <collision>
            <geometry>
                <box size="${base_length} ${base_width} ${base_height}"/> 
            </geometry>
            <origin xyz="0 0 0.1" rpy="0 0 0"/>
        </collision>
        <xacro:box_inertia m="5.0" l="${base_length}" w="${base_width}" h="${base_height}"
                            xyz="0 0 0.1"  rpy="0 0 0" />

    </link>  

    <joint name="base_joint" type="fixed">
        <origin xyz="0.0 0.0 0.15" rpy="0.0 0.0 0.0"/>
        <parent link="base_footprint"/>
        <child link="base_link"/>
    </joint>

    <link name="second_link">
        <visual>
            <geometry>
                <cylinder radius="${column_radius}" length="${column_length}"/>
            </geometry>
            <origin xyz="0 0 0.25" rpy="0 0 0" />    
            <material name="grey" />   
        </visual>
        <collision>
            <geometry>
                <cylinder radius="${column_radius}" length="${column_length}"/>
            </geometry>
            <origin xyz="0 0 0.25" rpy="0 0 0" />  
        </collision>
        <xacro:wheel_inertia m="1.0" r="${column_radius}" l="${column_length}"
                            xyz="0 0 0.25"  rpy="0.0 0.0 0.0" />   
    </link>


    <joint name="base_second_joint" type="fixed">
        <origin xyz="0.0 0.0 0.2" rpy="0.0 0.0 0.0"/>
        <parent link="base_link"/>
        <child link="second_link"/>
    </joint>


    
    <link name="rear_right_wheel_link">
        <visual>
            <geometry>
                <cylinder radius="${wheel_radius}" length="${wheel_length}"/>
            </geometry>
            <origin xyz="0.0 0.0 0.0" rpy="1.57 0.0 0.0"/>   
            <material name="black" />
        </visual>
        <collision>
            <geometry>
                <cylinder radius="${wheel_radius}" length="${wheel_length}"/>
            </geometry>
            <origin xyz="0.0 0.0 0.0" rpy="1.57 0.0 0.0"/>   
        </collision>
        <xacro:wheel_inertia m="1.0" r="${wheel_radius}" l="${wheel_length}"
                            xyz="0.0 0.0 0.0"  rpy="1.57 0.0 0.0" />      
    </link>

    <joint name="base_rear_right_wheel_joint" type="continuous">
        <origin xyz="-0.4 -0.3 0.0" rpy="0.0 0.0 0.0"/>
        <parent link="base_link"/>
        <child link="rear_right_wheel_link"/>
        <axis xyz="0.0 1.0 0.0"/>
    </joint>

    <link name="rear_left_wheel_link">
        <visual>
            <geometry>
                <cylinder radius="${wheel_radius}" length="${wheel_length}"/>
            </geometry>
            <origin xyz="0.0 0.0 0.0" rpy="1.57 0.0 0.0"/>   
            <material name="black" />
        </visual>  
        <collision>
            <geometry>
                <cylinder radius="${wheel_radius}" length="${wheel_length}"/>
            </geometry>
            <origin xyz="0.0 0.0 0.0" rpy="1.57 0.0 0.0"/>   
        </collision>
        <xacro:wheel_inertia m="1.0" r="${wheel_radius}" l="${wheel_length}"
                            xyz="0.0 0.0 0.0"  rpy="1.57 0.0 0.0" />      
    </link>

    <joint name="base_rear_left_wheel_joint" type="continuous">
        <origin xyz="-0.4 0.3 0.0" rpy="0.0 0.0 0.0"/>
        <parent link="base_link"/>
        <child link="rear_left_wheel_link"/>
        <axis xyz="0.0 1.0 0.0"/>
    </joint>

   
    

    <link name="front_right_wheel_link">
        <visual>
            <geometry>
                <cylinder radius="0.15" length="0.1"/>
            </geometry>
            <origin xyz="0.0 0.0 0.0" rpy="1.57 0.0 0.0"/>   
            <material name="black" />
        </visual>
        <collision>
            <geometry>
                <cylinder radius="${wheel_radius}" length="${wheel_length}"/>
            </geometry>
            <origin xyz="0.0 0.0 0.0" rpy="1.57 0.0 0.0"/>   
        </collision>
        <xacro:wheel_inertia m="1.0" r="${wheel_radius}" l="${wheel_length}"
                            xyz="0.0 0.0 0.0"  rpy="1.57 0.0 0.0" />        
    </link>

    <joint name="base_front_right_wheel_joint" type="continuous">
        <origin xyz="0.4 -0.3 0.0" rpy="0.0 0.0 0.0"/>
        <parent link="base_link"/>
        <child link="front_right_wheel_link"/>
        <axis xyz="0.0 1.0 0.0"/>
    </joint>

    <link name="front_left_wheel_link">
        <visual>
            <geometry>
                <cylinder radius="0.15" length="0.1"/>
            </geometry>
            <origin xyz="0.0 0.0 0.0" rpy="1.57 0.0 0.0"/>   
            <material name="black" />
        </visual>
        <collision>
            <geometry>
                <cylinder radius="${wheel_radius}" length="${wheel_length}"/>
            </geometry>
            <origin xyz="0.0 0.0 0.0" rpy="1.57 0.0 0.0"/>   
        </collision>
        <xacro:wheel_inertia m="1.0" r="${wheel_radius}" l="${wheel_length}"
                            xyz="0.0 0.0 0.0"  rpy="1.57 0.0 0.0" />        
    </link>

    <joint name="base_front_left_wheel_joint" type="continuous">
        <origin xyz="0.4 0.3 0.0" rpy="0.0 0.0 0.0"/>
        <parent link="base_link"/>
        <child link="front_left_wheel_link"/>
        <axis xyz="0.0 1.0 0.0"/>
    </joint>

</robot>
