<?xml version="1.0"?>
<robot name="car4">

    <material name="orange">
        <color rgba="1 0.6 0 1" />
    </material>

    <material name="grey">
        <color rgba="0.5 0.5 0.5 1" />
    </material>

    <material name="black">
        <color rgba="0.0 0.0 0.0 1" />
    </material>


    <link name="base_footprint">
    </link>


    <link name="base_link">
        <visual>
            <geometry>
                <box size="1 0.5 0.2"/> 
            </geometry>
            <origin xyz="0 0 0.1" rpy="0 0 0"/>
            <material name="orange" />
        </visual>
    </link>  

    <joint name="base_joint" type="fixed">
        <origin xyz="0.0 0.0 0.15" rpy="0.0 0.0 0.0"/>
        <parent link="base_footprint"/>
        <child link="base_link"/>
    </joint>

    <link name="second_link">
        <visual>
            <geometry>
                <cylinder radius="0.05" length="0.5"/>
            </geometry>
            <origin xyz="0 0 0.25" rpy="0 0 0" />    
            <material name="grey" />
        </visual>
    </link>

    <joint name="base_second_joint" type="revolute">
        <origin xyz="0.0 0.0 0.2" rpy="0.0 0.0 0.0"/>
        <parent link="base_link"/>
        <child link="second_link"/>
        <axis xyz="0.0 0.0 1"/>
        <limit lower="-1.57" upper="1.57" effort="100" velocity="100"/>
    </joint>
    





    <link name="back_right_wheel_link">
        <visual>
            <geometry>
                <cylinder radius="0.15" length="0.1"/>
            </geometry>
            <origin xyz="0.0 0.0 0.0" rpy="1.57 0.0 0.0"/>   
            <material name="black" />
        </visual>      
    </link>

    <joint name="base_back_right_wheel_joint" type="continuous">
        <origin xyz="-0.4 -0.3 0.0" rpy="0.0 0.0 0.0"/>
        <parent link="base_link"/>
        <child link="back_right_wheel_link"/>
        <axis xyz="0.0 1.0 0.0"/>
    </joint>

    <link name="back_left_wheel_link">
        <visual>
            <geometry>
                <cylinder radius="0.15" length="0.1"/>
            </geometry>
            <origin xyz="0.0 0.0 0.0" rpy="1.57 0.0 0.0"/>   
            <material name="black" />
        </visual>      
    </link>

    <joint name="base_back_left_wheel_joint" type="continuous">
        <origin xyz="-0.4 0.3 0.0" rpy="0.0 0.0 0.0"/>
        <parent link="base_link"/>
        <child link="back_left_wheel_link"/>
        <axis xyz="0.0 1.0 0.0"/>
    </joint>






    <link name="front_right_wheel_link">
        <visual>
            <geometry>
                <cylinder radius="0.15" length="0.1"/>
            </geometry>
            <origin xyz="0.0 0.0 0.0" rpy="1.57 0.0 0.0"/>   
            <material name="black" />
        </visual>      
    </link>

    <joint name="base_front_right_wheel_joint" type="continuous">
        <origin xyz="0.4 -0.3 0.0" rpy="0.0 0.0 0.0"/>
        <parent link="base_link"/>
        <child link="front_right_wheel_link"/>
        <axis xyz="0.0 1.0 0.0"/>
    </joint>

    <link name="front_left_wheel_link">
        <visual>
            <geometry>
                <cylinder radius="0.15" length="0.1"/>
            </geometry>
            <origin xyz="0.0 0.0 0.0" rpy="1.57 0.0 0.0"/>   
            <material name="black" />
        </visual>      
    </link>

    <joint name="base_front_left_wheel_joint" type="continuous">
        <origin xyz="0.4 0.3 0.0" rpy="0.0 0.0 0.0"/>
        <parent link="base_link"/>
        <child link="front_left_wheel_link"/>
        <axis xyz="0.0 1.0 0.0"/>
    </joint>

</robot>
